
<mujoco model="Whisker_composite">
<option timestep = "0.0002"></option>

<include file="Backdrop.xml"/>

  <option gravity="0 0 0"/>
  <extension>
    <plugin plugin="mujoco.elasticity.cable"/>
  </extension>

  <statistic center="0 0 0.2" extent="1"/>

  <compiler autolimits="true"/>

  <visual>
    <global elevation="0"/>
  </visual>

  <default>
    <geom solref="0.0005 0.009" solimp=".95 .99 .0001" margin = "0.0015"/>
  </default>

  <worldbody>

    <body name="Composit_whisker_body"  pos="0.0 0.0 0.5" euler="0 0 0">
    <site name="conti_whis_base_site" type="capsule" size="0.01 0.01" rgba="0 1 1 0.4" euler = "0 90 0" pos = "0.0183 0.0 0"/>
  
   <composite prefix="SegCom" type="cable" curve="s 0 0" count="21 1 1" size = "0.2"
       offset="0 0 0" initial="none">
  

   <plugin plugin="mujoco.elasticity.cable">
        
        <config key="twist" value="1e10"/>
       <config key="bend" value="3.1e9"/>
        <config key="vmax" value="0.1"/>
</plugin>

  <joint kind="main" type="hinge" axis ="0 1 0"  stiffness="0.01" damping="0.01" />
    <site ></site>
     
      <geom type="capsule" size="0.0015" rgba=".1 .2 .1 1" mass="1e-4" friction="01 0.1 0.1"/> <!--properties similar to Nylon 6/6-->
      
    </composite>


    </body>

   
  


  </worldbody>

<sensor> 
  <force name="base_force_sensor" site="conti_whis_base_site" />
  <torque name="base_torque_sensor" site="conti_whis_base_site"/>
</sensor>



</mujoco>
